<mujoco model="exoskeleton scene">
  <option gravity="0 0 -9.81" />
  <!-- <include file="exoskeleton.xml"/> -->
  <size nconmax="200" njmax="200" nstack="500000"/>
  <statistic center="0 0 1" extent="1.8"/>

  <visual>
    <headlight diffuse="0.6 0.6 0.6" ambient="0.3 0.3 0.3" specular="0 0 0"/>
    <rgba haze="0.15 0.25 0.35 1"/>
    <global azimuth="160" elevation="-20"/>
  </visual>

  <asset>
    <texture type="skybox" builtin="gradient" rgb1="0.3 0.5 0.7" rgb2="0 0 0" width="512" height="3072"/>
    <texture type="2d" name="groundplane" builtin="checker" mark="edge" rgb1="0.2 0.3 0.4" rgb2="0.1 0.2 0.3"
      markrgb="0.8 0.8 0.8" width="300" height="300"/>
    <material name="groundplane" texture="groundplane" texuniform="true" texrepeat="5 5" reflectance="0.2"/>
  </asset>

  <worldbody>
    <light pos="0 0 3.5" dir="0 0 -1" directional="true"/>
    <!-- 添加 friction 属性来增加地板的摩擦力 -->
    <!-- 第一个地面 -->
    <geom name="floor1" pos="0 0 0" size="10 10 0.05" type="plane" material="groundplane" friction="0.1 0.1 0.1"/>

    <!-- 左侧扶手 - 调整立杆位置和高度 -->
    <body name="left_handrail" pos="0 0 0">
      <inertial pos="-0.12833 -0.00625431 0.0426701" quat="0.0023652 0.77128 0.0526397 0.634312" mass="2.2828" diaginertia="0.0185807 0.0176686 0.00286415"/> 
      <joint name="Link_joint" pos="0.8 -0.25 1.075" axis="0 1 0" range="-180 180" actuatorfrcrange="-1000000 1000000"/> 
      <geom name="left_handrail_post1" type="cylinder" size="0.03" fromto="0.8 -0.25 0.075 0.8 -0.25 1.075" rgba="0.8 0.8 0.8 1"/>
    </body>



  </worldbody>
    <actuator>
        <!-- position controllers -->
        <position name='pos_Link_joint' joint="Link_joint" kp='5000' forcelimited="true" forcerange="-500 500"/>
        <!--velocity controllers-->
        <velocity name='vel_Link_joint' joint="Link_joint" kv='100' forcelimited="true" forcerange="-500 500"/>


        <!--torque controllers-->
        <motor name='trq_Link_joint' joint="Link_joint" gear='1' forcelimited="true" forcerange="-500 500"/>

        <!-- The torque controllers of Upper body joint -->
        <!-- <motor name='trq_torso_joint' joint="torso_joint" gear='1' forcelimited="true" forcerange="-200 200"/>
        <motor name='trq_RS_joint' joint="RS_joint" gear='1' forcelimited="true" forcerange="-200 200"/>
        <motor name='trq_R_elbow_joint' joint="R_elbow_joint" gear='1' forcelimited="true" forcerange="-200 200"/> -->
        <!-- <motor name='trq_R_hand_joint' joint="R_hand_joint" gear='1' forcelimited="true" forcerange="-200 200"/> -->
        <!-- <motor name='trq_LS_joint' joint="LS_joint" gear='1' forcelimited="true" forcerange="-200 200"/>
        <motor name='trq_L_elbow_joint' joint="L_elbow_joint" gear='1' forcelimited="true" forcerange="-200 200"/> -->
        <!-- <motor name='trq_L_hand_joint' joint="L_hand_joint" gear='1' forcelimited="true" forcerange="-200 200"/> -->
    </actuator>

    <sensor>
        <!--joint position sensors-->

        <jointpos  name="pos_Link_joint" joint="Link_joint"/>


        <!--joint velocity sensors-->

        <jointvel  name="vel_Link_joint" joint="Link_joint"/>


        <!--actuator torque sensors, note that these sensors are not for joints -->



    </sensor>

</mujoco>
